<?xml version="1.0"?>
<robot xmlns:xacro="http://www.ros.org/wiki/xacro"  name="hexapod_robot">

    <material name="white">
        <color rgba="1 1 1 1" />
    </material>

    <material name="orange">
        <color rgba="1 0.3 0.1 1"/>
    </material>

    <material name="black">
        <color rgba="0.1 0.1 0.1 1"/>
    </material>

    <material name="red">
        <color rgba="1 0 0 1"/>
    </material>
    
    <!-- Base Link
    <link name="base_link"/>

    <joint name="chassis_joint" type="fixed">
        <parent link="base_link"/>
        <child link="chassis"/>
        <origin xyz="0 0 0"/>
    </joint> -->
    
    <!-- Chassis link -->
    <link name="base_link">
        <visual>
            <origin xyz="0 0 0" rpy="0 0 0"/>
            <geometry>
		    <mesh filename="package://hexapod_pkg/meshes/base_link.stl" scale="1 1 1"/>
            </geometry>
            <material name="orange"/>
        </visual>
        <collision>
            <geometry>
		    <mesh filename="package://hexapod_pkg/meshes/base_link.stl" scale="1 1 1"/>
            </geometry>
        </collision>
        <inertial>
            <mass value="1.66723442"/>
            <inertia ixx="0.00977373" ixy="0.00001275" ixz="0.00023177" iyy="0.01042072" iyz="0.01042072" izz="0.01289955"/>
        </inertial>
    </link>
    
    <!-- chain 1 start -->
    <!-- joint 11 -->
    <joint name="joint_11" type="revolute">
        <parent link="base_link"/>
        <child link="thigh_link_11"/>
        <origin xyz="-0.06402054275 0.11088683276 0.028165" rpy="0 0 0"/>  <!-- Position relative to parent -->
        <axis xyz="0 0 -1"/>
        <limit lower="-1.0472" upper="2.0944" effort="4.5" velocity="3.0"/>
    </joint>

    <!-- Thigh Link 11 -->
    <link name="thigh_link_11">
        <visual>
            <origin xyz="0 0 0" rpy="0 0 0"/>
            <geometry>
                <mesh filename="package://hexapod_pkg/meshes/thigh_link_14.stl" scale="1 1 1"/>
            </geometry>
            <material name="white"/>
        </visual>
        <collision>
            <geometry>
                <mesh filename="package://hexapod_pkg/meshes/thigh_link_14.stl" scale="1 1 1"/>
            </geometry>
        </collision>
        <inertial>
            <mass value="0.1052"/>
            <inertia ixx="0.00032994" ixy="0.00000350" ixz="0" iyy="0.00003398" iyz="0" izz="0.00033378"/>
        </inertial>
    </link>

    <!-- joint 12 -->
    <joint name="joint_12" type="revolute">
        <parent link="thigh_link_11"/>
        <child link="shin_link_12"/>
        <origin xyz="0 0.07109 0" rpy="0 0 0"/>  <!-- Position relative to parent -->
        <axis xyz="1 0 0"/>
        <limit lower="-1.5712" upper="1.5712" effort="4.5" velocity="3.0"/>
    </joint>

    <!-- Shin Link 12 -->
    <link name="shin_link_12">
        <visual>
            <origin xyz="0 0 0" rpy="0 0 0"/>
            <geometry>
                <mesh filename="package://hexapod_pkg/meshes/shin_link_14.stl" scale="1 1 1"/>
            </geometry>
            <material name="black"/>
        </visual>
        <collision>
            <geometry>
                <mesh filename="package://hexapod_pkg/meshes/shin_link_14.stl" scale="1 1 1"/>
            </geometry>
        </collision>
        <inertial>
            <mass value="0.1011"/>
            <inertia ixx="0.00043187" ixy="0.00000399" ixz="0" iyy="0.00003189" iyz="0" izz="0.00045027"/>
        </inertial>
    </link>

    <!-- joint 13 -->
    <joint name="joint_13" type="revolute">
        <parent link="shin_link_12"/>
        <child link="foot_link_13"/>
        <origin xyz="0 0.08109 0" rpy="0 0 0"/>  <!-- Position relative to parent -->
        <axis xyz="1 0 0"/>
        <limit lower="-1.5712" upper="1.5712" effort="4.5" velocity="3.0"/>
    </joint>

    <!-- Foot Link 13 -->
    <link name="foot_link_13">
        <visual>
            <origin xyz="0 0 0" rpy="0 0 0"/>
            <geometry>
                <mesh filename="package://hexapod_pkg/meshes/foot_link_14.stl" scale="1 1 1"/>
            </geometry>
            <material name="red"/>
        </visual>
        <collision>
            <geometry>
                <mesh filename="package://hexapod_pkg/meshes/foot_link_14.stl" scale="1 1 1"/>
            </geometry>
        </collision>
        <inertial>
            <mass value="0.03702"/>
            <inertia ixx="0.00023291" ixy="0" ixz="0" iyy="0.00002537" iyz="-0.00004175" izz="0.00023879"/>
        </inertial>
    </link>
    <!-- chain 1 end -->

    <!-- chain 4 start -->
    <!-- joint 41 -->
    <joint name="joint_41" type="revolute">
        <parent link="base_link"/>
        <child link="thigh_link_41"/>
        <origin xyz="0.06402054275 0.11088683276 0.028165" rpy="0 0 0"/>  <!-- Position relative to parent -->
        <axis xyz="0 0 1"/>
        <limit lower="-2.0944" upper="1.0472" effort="4.5" velocity="3.0"/>
    </joint>

    <!-- Thigh Link 41 -->
    <link name="thigh_link_41">
        <visual>
            <origin xyz="0 0 0" rpy="0 0 0"/>
            <geometry>
                <mesh filename="package://hexapod_pkg/meshes/thigh_link_14.stl" scale="1 1 1"/>
            </geometry>
            <material name="white"/>
        </visual>
        <collision>
            <geometry>
                <mesh filename="package://hexapod_pkg/meshes/thigh_link_14.stl" scale="1 1 1"/>
            </geometry>
        </collision>
        <inertial>
            <mass value="0.1052"/>
            <inertia ixx="0.00032994" ixy="0.00000350" ixz="0" iyy="0.00003398" iyz="0" izz="0.00033378"/>
        </inertial>
    </link>

    <!-- joint 42 -->
    <joint name="joint_42" type="revolute">
        <parent link="thigh_link_41"/>
        <child link="shin_link_42"/>
        <origin xyz="0 0.07109 0" rpy="0 0 0"/>  <!-- Position relative to parent -->
        <axis xyz="1 0 0"/>
        <limit lower="-1.5712" upper="1.5712" effort="4.5" velocity="3.0"/>
    </joint>

    <!-- Shin Link 42 -->
    <link name="shin_link_42">
        <visual>
            <origin xyz="0 0 0" rpy="0 0 0"/>
            <geometry>
                <mesh filename="package://hexapod_pkg/meshes/shin_link_14.stl" scale="1 1 1"/>
            </geometry>
            <material name="black"/>
        </visual>
        <collision>
            <geometry>
                <mesh filename="package://hexapod_pkg/meshes/shin_link_14.stl" scale="1 1 1"/>
            </geometry>
        </collision>
        <inertial>
            <mass value="0.1011"/>
            <inertia ixx="0.00043187" ixy="0.00000399" ixz="0" iyy="0.00003189" iyz="0" izz="0.00045027"/>
        </inertial>
    </link>

    <!-- joint 43 -->
    <joint name="joint_43" type="revolute">
        <parent link="shin_link_42"/>
        <child link="foot_link_43"/>
        <origin xyz="0 0.08109 0" rpy="0 0 0"/>  <!-- Position relative to parent -->
        <axis xyz="1 0 0"/>
        <limit lower="-1.5712" upper="1.5712" effort="4.5" velocity="3.0"/>
    </joint>

    <!-- Foot Link 43 -->
    <link name="foot_link_43">
        <visual>
            <origin xyz="0 0 0" rpy="0 0 0"/>
            <geometry>
                <mesh filename="package://hexapod_pkg/meshes/foot_link_14.stl" scale="1 1 1"/>
            </geometry>
            <material name="red"/>
        </visual>
        <collision>
            <geometry>
                <mesh filename="package://hexapod_pkg/meshes/foot_link_14.stl" scale="1 1 1"/>
            </geometry>
        </collision>
        <inertial>
            <mass value="0.03702"/>
            <inertia ixx="0.00023291" ixy="0" ixz="0" iyy="0.00002537" iyz="-0.00004175" izz="0.00023879"/>
        </inertial>
    </link>
    <!-- chain 4 end -->

    <!-- chain 2 start -->
    <!-- joint 21 -->
    <joint name="joint_21" type="revolute">
        <parent link="base_link"/>
        <child link="thigh_link_21"/>
        <origin xyz="-0.12804108549 0 0.028165" rpy="0 0 0"/>  <!-- Position relative to parent -->
        <axis xyz="0 0 -1"/>
        <limit lower="-1.5712" upper="1.5712" effort="4.5" velocity="3.0"/>
    </joint>

    <!-- Thigh Link 21 -->
    <link name="thigh_link_21">
        <visual>
            <origin xyz="0 0 0" rpy="0 0 0"/>
            <geometry>
                <mesh filename="package://hexapod_pkg/meshes/thigh_link_2.stl" scale="1 1 1"/>
            </geometry>
            <material name="white"/>
        </visual>
        <collision>
            <geometry>
                <mesh filename="package://hexapod_pkg/meshes/thigh_link_2.stl" scale="1 1 1"/>
            </geometry>
        </collision>
        <inertial>
            <mass value="0.1052"/>
            <inertia ixx="0.00003398" ixy="-0.00000350" ixz="0" iyy="0.00032994" iyz="0" izz="0.00033378"/>
        </inertial>
    </link>

    <!-- joint 22 -->
    <joint name="joint_22" type="revolute">
        <parent link="thigh_link_21"/>
        <child link="shin_link_22"/>
        <origin xyz="-0.07109 0 0" rpy="0 0 0"/>  <!-- Position relative to parent -->
        <axis xyz="0 1 0"/>
        <limit lower="-1.5712" upper="1.5712" effort="4.5" velocity="3.0"/>
    </joint>

    <!-- Shin Link 22 -->
    <link name="shin_link_22">
        <visual>
            <origin xyz="0 0 0" rpy="0 0 0"/>
            <geometry>
                <mesh filename="package://hexapod_pkg/meshes/shin_link_2.stl" scale="1 1 1"/>
            </geometry>
            <material name="black"/>
        </visual>
        <collision>
            <geometry>
                <mesh filename="package://hexapod_pkg/meshes/shin_link_2.stl" scale="1 1 1"/>
            </geometry>
        </collision>
        <inertial>
            <mass value="0.1011"/>
            <inertia ixx="0.00003189" ixy="-0.00000399" ixz="0" iyy="0.00043187" iyz="0" izz="0.00045027"/>
        </inertial>
    </link>

    <!-- joint 23 -->
    <joint name="joint_23" type="revolute">
        <parent link="shin_link_22"/>
        <child link="foot_link_23"/>
        <origin xyz="-0.08109 0 0" rpy="0 0 0"/>  <!-- Position relative to parent -->
        <axis xyz="0 1 0"/>
        <limit lower="-1.5712" upper="1.5712" effort="4.5" velocity="3.0"/>
    </joint>

    <!-- Foot Link 23 -->
    <link name="foot_link_23">
        <visual>
            <origin xyz="0 0 0" rpy="0 0 0"/>
            <geometry>
                <mesh filename="package://hexapod_pkg/meshes/foot_link_2.stl" scale="1 1 1"/>
            </geometry>
            <material name="white"/>
        </visual>
        <collision>
            <geometry>
                <mesh filename="package://hexapod_pkg/meshes/foot_link_2.stl" scale="1 1 1"/>
            </geometry>
        </collision>
        <inertial>
            <mass value="0.03702"/>
            <inertia ixx="0.00002537" ixy="0" ixz="0.00004175" iyy="0.00023291" iyz="0" izz="0.00023879"/>
        </inertial>
    </link>
    <!-- chain 2 end -->

    <!-- chain 5 start -->
    <!-- joint 51 -->
    <joint name="joint_51" type="revolute">
        <parent link="base_link"/>
        <child link="thigh_link_51"/>
        <origin xyz="0.12804108549 0 0.028165" rpy="0 0 0"/>  <!-- Position relative to parent -->
        <axis xyz="0 0 1"/>
        <limit lower="-1.5712" upper="1.5712" effort="4.5" velocity="3.0"/>
    </joint>

    <!-- Thigh Link 51 -->
    <link name="thigh_link_51">
        <visual>
            <origin xyz="0 0 0" rpy="0 0 0"/>
            <geometry>
                <mesh filename="package://hexapod_pkg/meshes/thigh_link_5.stl" scale="1 1 1"/>
            </geometry>
            <material name="white"/>
        </visual>
        <collision>
            <geometry>
                <mesh filename="package://hexapod_pkg/meshes/thigh_link_5.stl" scale="1 1 1"/>
            </geometry>
        </collision>
        <inertial>
            <mass value="0.1052"/>
            <inertia ixx="0.00003398" ixy="-0.00000350" ixz="0" iyy="0.00032994" iyz="0" izz="0.00033378"/>
        </inertial>
    </link>

    <!-- joint 52 -->
    <joint name="joint_52" type="revolute">
        <parent link="thigh_link_51"/>
        <child link="shin_link_52"/>
        <origin xyz="0.07109 0 0" rpy="0 0 0"/>  <!-- Position relative to parent -->
        <axis xyz="0 -1 0"/>
        <limit lower="-1.5712" upper="1.5712" effort="4.5" velocity="3.0"/>
    </joint>

    <!-- Shin Link 52 -->
    <link name="shin_link_52">
        <visual>
            <origin xyz="0 0 0" rpy="0 0 0"/>
            <geometry>
                <mesh filename="package://hexapod_pkg/meshes/shin_link_5.stl" scale="1 1 1"/>
            </geometry>
            <material name="black"/>
        </visual>
        <collision>
            <geometry>
                <mesh filename="package://hexapod_pkg/meshes/shin_link_5.stl" scale="1 1 1"/>
            </geometry>
        </collision>
        <inertial>
            <mass value="0.1011"/>
            <inertia ixx="0.00003189" ixy="-0.00000399" ixz="0" iyy="0.00043187" iyz="0" izz="0.00045027"/>
        </inertial>
    </link>

    <!-- joint 53 -->
    <joint name="joint_53" type="revolute">
        <parent link="shin_link_52"/>
        <child link="foot_link_53"/>
        <origin xyz="0.08109 0 0" rpy="0 0 0"/>  <!-- Position relative to parent -->
        <axis xyz="0 -1 0"/>
        <limit lower="-1.5712" upper="1.5712" effort="4.5" velocity="3.0"/>
    </joint>

    <!-- Foot Link 53 -->
    <link name="foot_link_53">
        <visual>
            <origin xyz="0 0 0" rpy="0 0 0"/>
            <geometry>
                <mesh filename="package://hexapod_pkg/meshes/foot_link_5.stl" scale="1 1 1"/>
            </geometry>
            <material name="white"/>
        </visual>
        <collision>
            <geometry>
                <mesh filename="package://hexapod_pkg/meshes/foot_link_5.stl" scale="1 1 1"/>
            </geometry>
        </collision>
        <inertial>
            <mass value="0.03702"/>
            <inertia ixx="0.00002537" ixy="0" ixz="0.00004175" iyy="0.00023291" iyz="0" izz="0.00023879"/>
        </inertial>
    </link>
    <!-- chain 5 end -->

    <!-- chain 6 start -->
    <!-- joint 61 -->
    <joint name="joint_61" type="revolute">
        <parent link="base_link"/>
        <child link="thigh_link_61"/>
        <origin xyz="0.06402054275 -0.11088683276 0.028165" rpy="0 0 0"/>  <!-- Position relative to parent -->
        <axis xyz="0 0 1"/>
        <limit lower="-1.0472" upper="2.0944" effort="4.5" velocity="3.0"/>
    </joint>

    <!-- Thigh Link 61 -->
    <link name="thigh_link_61">
        <visual>
            <origin xyz="0 0 0" rpy="0 0 0"/>
            <geometry>
                <mesh filename="package://hexapod_pkg/meshes/thigh_link_36.stl" scale="1 1 1"/>
            </geometry>
            <material name="white"/>
        </visual>
        <collision>
            <geometry>
                <mesh filename="package://hexapod_pkg/meshes/thigh_link_36.stl" scale="1 1 1"/>
            </geometry>
        </collision>
        <inertial>
            <mass value="0.1052"/>
            <inertia ixx="0.00032994" ixy="0.00000350" ixz="0" iyy="0.00003398" iyz="0" izz="0.00033378"/>
        </inertial>
    </link>

    <!-- joint 62 -->
    <joint name="joint_62" type="revolute">
        <parent link="thigh_link_61"/>
        <child link="shin_link_62"/>
        <origin xyz="0 -0.07109 0" rpy="0 0 0"/>  <!-- Position relative to parent -->
        <axis xyz="-1 0 0"/>
        <limit lower="-1.5712" upper="1.5712" effort="4.5" velocity="3.0"/>
    </joint>

    <!-- Shin Link 62 -->
    <link name="shin_link_62">
        <visual>
            <origin xyz="0 0 0" rpy="0 0 0"/>
            <geometry>
                <mesh filename="package://hexapod_pkg/meshes/shin_link_36.stl" scale="1 1 1"/>
            </geometry>
            <material name="black"/>
        </visual>
        <collision>
            <geometry>
                <mesh filename="package://hexapod_pkg/meshes/shin_link_36.stl" scale="1 1 1"/>
            </geometry>
        </collision>
        <inertial>
            <mass value="0.1011"/>
            <inertia ixx="0.00043187" ixy="0.00000399" ixz="0" iyy="0.00003189" iyz="0" izz="0.00045027"/>
        </inertial>
    </link>

    <!-- joint 63 -->
    <joint name="joint_63" type="revolute">
        <parent link="shin_link_62"/>
        <child link="foot_link_63"/>
        <origin xyz="0 -0.08109 0" rpy="0 0 0"/>  <!-- Position relative to parent -->
        <axis xyz="-1 0 0"/>
        <limit lower="-1.5712" upper="1.5712" effort="4.5" velocity="3.0"/>
    </joint>

    <!-- Foot Link 63 -->
    <link name="foot_link_63">
        <visual>
            <origin xyz="0 0 0" rpy="0 0 0"/>
            <geometry>
                <mesh filename="package://hexapod_pkg/meshes/foot_link_36.stl" scale="1 1 1"/>
            </geometry>
            <material name="white"/>
        </visual>
        <collision>
            <geometry>
                <mesh filename="package://hexapod_pkg/meshes/foot_link_36.stl" scale="1 1 1"/>
            </geometry>
        </collision>
        <inertial>
            <mass value="0.03702"/>
            <inertia ixx="0.00023291" ixy="0" ixz="0" iyy="0.00002537" iyz="-0.00004175" izz="0.00023879"/>
        </inertial>
    </link>
    <!-- chain 6 end -->

    <!-- chain 3 start -->
    <!-- joint 31 -->
    <joint name="joint_31" type="revolute">
        <parent link="base_link"/>
        <child link="thigh_link_31"/>
        <origin xyz="-0.06402054275 -0.11088683276 0.028165" rpy="0 0 0"/>  <!-- Position relative to parent -->
        <axis xyz="0 0 -1"/>
        <limit lower="-2.0944" upper="1.0472" effort="4.5" velocity="3.0"/>
    </joint>

    <!-- Thigh Link 31 -->
    <link name="thigh_link_31">
        <visual>
            <origin xyz="0 0 0" rpy="0 0 0"/>
            <geometry>
                <mesh filename="package://hexapod_pkg/meshes/thigh_link_36.stl" scale="1 1 1"/>
            </geometry>
            <material name="white"/>
        </visual>
        <collision>
            <geometry>
                <mesh filename="package://hexapod_pkg/meshes/thigh_link_36.stl" scale="1 1 1"/>
            </geometry>
        </collision>
        <inertial>
            <mass value="0.1052"/>
            <inertia ixx="0.00032994" ixy="0.00000350" ixz="0" iyy="0.00003398" iyz="0" izz="0.00033378"/>
        </inertial>
    </link>

    <!-- joint 32 -->
    <joint name="joint_32" type="revolute">
        <parent link="thigh_link_31"/>
        <child link="shin_link_32"/>
        <origin xyz="0 -0.07109 0" rpy="0 0 0"/>  <!-- Position relative to parent -->
        <axis xyz="-1 0 0"/>
        <limit lower="-1.5712" upper="1.5712" effort="4.5" velocity="3.0"/>
    </joint>

    <!-- Shin Link 32 -->
    <link name="shin_link_32">
        <visual>
            <origin xyz="0 0 0" rpy="0 0 0"/>
            <geometry>
                <mesh filename="package://hexapod_pkg/meshes/shin_link_36.stl" scale="1 1 1"/>
            </geometry>
            <material name="black"/>
        </visual>
        <collision>
            <geometry>
                <mesh filename="package://hexapod_pkg/meshes/shin_link_36.stl" scale="1 1 1"/>
            </geometry>
        </collision>
        <inertial>
            <mass value="0.1011"/>
            <inertia ixx="0.00043187" ixy="0.00000399" ixz="0" iyy="0.00003189" iyz="0" izz="0.00045027"/>
        </inertial>
    </link>

    <!-- joint 33 -->
    <joint name="joint_33" type="revolute">
        <parent link="shin_link_32"/>
        <child link="foot_link_33"/>
        <origin xyz="0 -0.08109 0" rpy="0 0 0"/>  <!-- Position relative to parent -->
        <axis xyz="-1 0 0"/>
        <limit lower="-1.5712" upper="1.5712" effort="4.5" velocity="3.0"/>
    </joint>

    <!-- Foot Link 33 -->
    <link name="foot_link_33">
        <visual>
            <origin xyz="0 0 0" rpy="0 0 0"/>
            <geometry>
                <mesh filename="package://hexapod_pkg/meshes/foot_link_36.stl" scale="1 1 1"/>
            </geometry>
            <material name="white"/>
        </visual>
        <collision>
            <geometry>
                <mesh filename="package://hexapod_pkg/meshes/foot_link_36.stl" scale="1 1 1"/>
            </geometry>
        </collision>
        <inertial>
            <mass value="0.03702"/>
            <inertia ixx="0.00023291" ixy="0" ixz="0" iyy="0.00002537" iyz="-0.00004175" izz="0.00023879"/>
        </inertial>
    </link>
    <!-- chain 3 end -->

    <!-- gazebo control -->
    <!-- LEG 1 -->
    <transmission name="trans_joint_11">
        <type>transmission_interface/SimpleTransmission</type>
        <joint name="joint_11">
            <hardwareInterface>hardware_interface/PositionJointInterface</hardwareInterface>
        </joint>
        <actuator name="trans_joint_11_motor">
            <hardwareInterface>hardware_interface/PositionJointInterface</hardwareInterface>
            <mechanicalReduction>1</mechanicalReduction>
        </actuator>
    </transmission>

    <transmission name="trans_joint_12">
    <type>transmission_interface/SimpleTransmission</type>
    <joint name="joint_12">
        <hardwareInterface>hardware_interface/PositionJointInterface</hardwareInterface>
    </joint>
    <actuator name="trans_joint_12_motor">
        <hardwareInterface>hardware_interface/PositionJointInterface</hardwareInterface>
        <mechanicalReduction>1</mechanicalReduction>
    </actuator>
    </transmission>

    <transmission name="trans_joint_13">
    <type>transmission_interface/SimpleTransmission</type>
    <joint name="joint_13">
        <hardwareInterface>hardware_interface/PositionJointInterface</hardwareInterface>
    </joint>
    <actuator name="trans_joint_13_motor">
        <hardwareInterface>hardware_interface/PositionJointInterface</hardwareInterface>
        <mechanicalReduction>1</mechanicalReduction>
    </actuator>
    </transmission>

    <!-- LEG 2 -->
    <transmission name="trans_joint_21">
    <type>transmission_interface/SimpleTransmission</type>
    <joint name="joint_21">
        <hardwareInterface>hardware_interface/PositionJointInterface</hardwareInterface>
    </joint>
    <actuator name="trans_joint_21_motor">
        <hardwareInterface>hardware_interface/PositionJointInterface</hardwareInterface>
        <mechanicalReduction>1</mechanicalReduction>
    </actuator>
    </transmission>

    <transmission name="trans_joint_22">
    <type>transmission_interface/SimpleTransmission</type>
    <joint name="joint_22">
        <hardwareInterface>hardware_interface/PositionJointInterface</hardwareInterface>
    </joint>
    <actuator name="trans_joint_22_motor">
        <hardwareInterface>hardware_interface/PositionJointInterface</hardwareInterface>
        <mechanicalReduction>1</mechanicalReduction>
    </actuator>
    </transmission>

    <transmission name="trans_joint_23">
    <type>transmission_interface/SimpleTransmission</type>
    <joint name="joint_23">
        <hardwareInterface>hardware_interface/PositionJointInterface</hardwareInterface>
    </joint>
    <actuator name="trans_joint_23_motor">
        <hardwareInterface>hardware_interface/PositionJointInterface</hardwareInterface>
        <mechanicalReduction>1</mechanicalReduction>
    </actuator>
    </transmission>

    <!-- LEG 3 -->
    <transmission name="trans_joint_31">
    <type>transmission_interface/SimpleTransmission</type>
    <joint name="joint_31">
        <hardwareInterface>hardware_interface/PositionJointInterface</hardwareInterface>
    </joint>
    <actuator name="trans_joint_31_motor">
        <hardwareInterface>hardware_interface/PositionJointInterface</hardwareInterface>
        <mechanicalReduction>1</mechanicalReduction>
    </actuator>
    </transmission>

    <transmission name="trans_joint_32">
    <type>transmission_interface/SimpleTransmission</type>
    <joint name="joint_32">
        <hardwareInterface>hardware_interface/PositionJointInterface</hardwareInterface>
    </joint>
    <actuator name="trans_joint_32_motor">
        <hardwareInterface>hardware_interface/PositionJointInterface</hardwareInterface>
        <mechanicalReduction>1</mechanicalReduction>
    </actuator>
    </transmission>

    <transmission name="trans_joint_33">
    <type>transmission_interface/SimpleTransmission</type>
    <joint name="joint_33">
        <hardwareInterface>hardware_interface/PositionJointInterface</hardwareInterface>
    </joint>
    <actuator name="trans_joint_33_motor">
        <hardwareInterface>hardware_interface/PositionJointInterface</hardwareInterface>
        <mechanicalReduction>1</mechanicalReduction>
    </actuator>
    </transmission>

    <!-- LEG 4 -->
    <transmission name="trans_joint_41">
    <type>transmission_interface/SimpleTransmission</type>
    <joint name="joint_41">
        <hardwareInterface>hardware_interface/PositionJointInterface</hardwareInterface>
    </joint>
    <actuator name="trans_joint_41_motor">
        <hardwareInterface>hardware_interface/PositionJointInterface</hardwareInterface>
        <mechanicalReduction>1</mechanicalReduction>
    </actuator>
    </transmission>

    <transmission name="trans_joint_42">
    <type>transmission_interface/SimpleTransmission</type>
    <joint name="joint_42">
        <hardwareInterface>hardware_interface/PositionJointInterface</hardwareInterface>
    </joint>
    <actuator name="trans_joint_42_motor">
        <hardwareInterface>hardware_interface/PositionJointInterface</hardwareInterface>
        <mechanicalReduction>1</mechanicalReduction>
    </actuator>
    </transmission>

    <transmission name="trans_joint_43">
    <type>transmission_interface/SimpleTransmission</type>
    <joint name="joint_43">
        <hardwareInterface>hardware_interface/PositionJointInterface</hardwareInterface>
    </joint>
    <actuator name="trans_joint_43_motor">
        <hardwareInterface>hardware_interface/PositionJointInterface</hardwareInterface>
        <mechanicalReduction>1</mechanicalReduction>
    </actuator>
    </transmission>

    <!-- LEG 5 -->
    <transmission name="trans_joint_51">
    <type>transmission_interface/SimpleTransmission</type>
    <joint name="joint_51">
        <hardwareInterface>hardware_interface/PositionJointInterface</hardwareInterface>
    </joint>
    <actuator name="trans_joint_51_motor">
        <hardwareInterface>hardware_interface/PositionJointInterface</hardwareInterface>
        <mechanicalReduction>1</mechanicalReduction>
    </actuator>
    </transmission>

    <transmission name="trans_joint_52">
    <type>transmission_interface/SimpleTransmission</type>
    <joint name="joint_52">
        <hardwareInterface>hardware_interface/PositionJointInterface</hardwareInterface>
    </joint>
    <actuator name="trans_joint_52_motor">
        <hardwareInterface>hardware_interface/PositionJointInterface</hardwareInterface>
        <mechanicalReduction>1</mechanicalReduction>
    </actuator>
    </transmission>

    <transmission name="trans_joint_53">
    <type>transmission_interface/SimpleTransmission</type>
    <joint name="joint_53">
        <hardwareInterface>hardware_interface/PositionJointInterface</hardwareInterface>
    </joint>
    <actuator name="trans_joint_53_motor">
        <hardwareInterface>hardware_interface/PositionJointInterface</hardwareInterface>
        <mechanicalReduction>1</mechanicalReduction>
    </actuator>
    </transmission>

    <!-- LEG 6 -->
    <transmission name="trans_joint_61">
    <type>transmission_interface/SimpleTransmission</type>
    <joint name="joint_61">
        <hardwareInterface>hardware_interface/PositionJointInterface</hardwareInterface>
    </joint>
    <actuator name="trans_joint_61_motor">
        <hardwareInterface>hardware_interface/PositionJointInterface</hardwareInterface>
        <mechanicalReduction>1</mechanicalReduction>
    </actuator>
    </transmission>

    <transmission name="trans_joint_62">
    <type>transmission_interface/SimpleTransmission</type>
    <joint name="joint_62">
        <hardwareInterface>hardware_interface/PositionJointInterface</hardwareInterface>
    </joint>
    <actuator name="trans_joint_62_motor">
        <hardwareInterface>hardware_interface/PositionJointInterface</hardwareInterface>
        <mechanicalReduction>1</mechanicalReduction>
    </actuator>
    </transmission>

    <transmission name="trans_joint_63">
    <type>transmission_interface/SimpleTransmission</type>
    <joint name="joint_63">
        <hardwareInterface>hardware_interface/PositionJointInterface</hardwareInterface>
    </joint>
    <actuator name="trans_joint_63_motor">
        <hardwareInterface>hardware_interface/PositionJointInterface</hardwareInterface>
        <mechanicalReduction>1</mechanicalReduction>
    </actuator>
    </transmission>


    <gazebo>
        <plugin name="gazebo_ros_control" filename="libgazebo_ros_control.so">
            <robotNamespace>/</robotNamespace>
        </plugin>
    </gazebo>

    <gazebo reference="base_link">
    	<material>Gazebo/Black</material>
    </gazebo>
    <gazebo reference="thigh_link_11">
    	<material>Gazebo/White</material>
    </gazebo>
    <gazebo reference="thigh_link_21">
    	<material>Gazebo/White</material>
    </gazebo>
    <gazebo reference="thigh_link_31">
    	<material>Gazebo/White</material>
    </gazebo>
    <gazebo reference="thigh_link_41">
    	<material>Gazebo/White</material>
    </gazebo>
    <gazebo reference="thigh_link_51">
    	<material>Gazebo/White</material>
    </gazebo>
    <gazebo reference="thigh_link_61">
    	<material>Gazebo/White</material>
    </gazebo>
    <gazebo reference="shin_link_12">
    	<material>Gazebo/Black</material>
    </gazebo>
    <gazebo reference="shin_link_22">
    	<material>Gazebo/Black</material>
    </gazebo>
    <gazebo reference="shin_link_32">
    	<material>Gazebo/Black</material>
    </gazebo>
    <gazebo reference="shin_link_42">
    	<material>Gazebo/Black</material>
    </gazebo>
    <gazebo reference="shin_link_52">
    	<material>Gazebo/Black</material>
    </gazebo>
    <gazebo reference="shin_link_62">
    	<material>Gazebo/Black</material>
    </gazebo>
    <gazebo reference="foot_link_13">
    	<material>Gazebo/White</material>
    </gazebo>
    <gazebo reference="foot_link_23">
    	<material>Gazebo/White</material>
    </gazebo>
    <gazebo reference="foot_link_33">
    	<material>Gazebo/White</material>
    </gazebo>
    <gazebo reference="foot_link_43">
    	<material>Gazebo/White</material>
    </gazebo>
    <gazebo reference="foot_link_53">
    	<material>Gazebo/White</material>
    </gazebo>
    <gazebo reference="foot_link_63">
    	<material>Gazebo/White</material>
    </gazebo>
    
</robot>
