<?xml version="1.0"?>
<robot name="hexapod_robot">
    
    <!-- Base Link (Chassis) -->
    <link name="base_link">
        <visual>
            <origin xyz="0 0 0" rpy="0 0 0"/>
            <geometry>
                <mesh filename="package://robot_urdf/meshes/base_link.stl" scale="1 1 1"/>
            </geometry>
            <material name="black">
                <color rgba="0.1 0.1 0.1 1"/>
            </material>
        </visual>
        <collision>
            <geometry>
                <mesh filename="package://robot_urdf/meshes/base_link.stl" scale="1 1 1"/>
            </geometry>
        </collision>
        <!-- <inertial>
            <mass value="1.64932704"/>
            <inertia ixx="0.00743093" ixy="0.00003990" ixz="-0.00023108" iyy="0.00755492" iyz="0.00010952" izz="0.01279979"/>
        </inertial> -->
    </link>
    
    <!-- chain 1 start -->
    <!-- joint 11 -->
    <joint name="joint_11" type="revolute">
        <parent link="base_link"/>
        <child link="thigh_link_11"/>
        <origin xyz="-0.06402054275 0.11088683276 0.028165" rpy="0 0 0"/>  <!-- Position relative to parent -->
        <axis xyz="0 0 1"/>
        <limit lower="-1.0472" upper="2.0944" effort="4.5" velocity="3.0"/>
    </joint>

    <!-- Thigh Link 11 -->
    <link name="thigh_link_11">
        <visual>
            <origin xyz="0 0 0" rpy="0 0 0"/>
            <geometry>
                <mesh filename="package://robot_urdf/meshes/thigh_link_14.stl" scale="1 1 1"/>
            </geometry>
            <material name="white">
                <color rgba="0.9 0.9 0.9 1"/>
            </material>
        </visual>
        <collision>
            <geometry>
                <mesh filename="package://robot_urdf/meshes/thigh_link_14.stl" scale="1 1 1"/>
            </geometry>
        </collision>
        <inertial>
            <mass value="0.13695392"/>
            <inertia ixx="0.00008188" ixy="0.00000025" ixz="0" iyy="0.00005137" iyz="0.00000016" izz="0.00007680"/>
        </inertial>
    </link>

    <!-- joint 12 -->
    <joint name="joint_12" type="revolute">
        <parent link="thigh_link_11"/>
        <child link="shin_link_12"/>
        <origin xyz="0 0.07109 0" rpy="0 0 0"/>  <!-- Position relative to parent -->
        <axis xyz="1 0 0"/>
        <limit lower="-1.5712" upper="1.5712" effort="4.5" velocity="3.0"/>
    </joint>

    <!-- Shin Link 12 -->
    <link name="shin_link_12">
        <visual>
            <origin xyz="0 0 0" rpy="0 0 0"/>
            <geometry>
                <mesh filename="package://robot_urdf/meshes/shin_link_14.stl" scale="1 1 1"/>
            </geometry>
            <material name="white">
                <color rgba="0.1 0.1 0.1 1"/>
            </material>
        </visual>
        <collision>
            <geometry>
                <mesh filename="package://robot_urdf/meshes/shin_link_14.stl" scale="1 1 1"/>
            </geometry>
        </collision>
        <inertial>
            <mass value="0.15177213"/>
            <inertia ixx="0.00008751" ixy="0.00000046" ixz="0" iyy="0.00006200" iyz="0" izz="0.00012088"/>
        </inertial>
    </link>

    <!-- joint 13 -->
    <joint name="joint_13" type="revolute">
        <parent link="shin_link_12"/>
        <child link="foot_link_13"/>
        <origin xyz="0 0.08109 0" rpy="0 0 0"/>  <!-- Position relative to parent -->
        <axis xyz="1 0 0"/>
        <limit lower="-1.5712" upper="1.5712" effort="4.5" velocity="3.0"/>
    </joint>

    <!-- Foot Link 13 -->
    <link name="foot_link_13">
        <visual>
            <origin xyz="0 0 0" rpy="0 0 0"/>
            <geometry>
                <mesh filename="package://robot_urdf/meshes/foot_link_14.stl" scale="1 1 1"/>
            </geometry>
            <material name="white">
                <color rgba="0.9 0.9 0.9 1"/>
            </material>
        </visual>
        <collision>
            <geometry>
                <mesh filename="package://robot_urdf/meshes/foot_link_14.stl" scale="1 1 1"/>
            </geometry>
        </collision>
        <inertial>
            <mass value="0.08684425"/>
            <inertia ixx="0.00013083" ixy="0.00000021" ixz="-0.00000003" iyy="0.00004844" iyz="-0.00003099" izz="0.00015571"/>
        </inertial>
    </link>
    <!-- chain 1 end -->

    <!-- chain 4 start -->
    <!-- joint 41 -->
    <joint name="joint_41" type="revolute">
        <parent link="base_link"/>
        <child link="thigh_link_41"/>
        <origin xyz="0.06402054275 0.11088683276 0.028165" rpy="0 0 0"/>  <!-- Position relative to parent -->
        <axis xyz="0 0 1"/>
        <limit lower="-2.0944" upper="1.0472" effort="4.5" velocity="3.0"/>
    </joint>

    <!-- Thigh Link 41 -->
    <link name="thigh_link_41">
        <visual>
            <origin xyz="0 0 0" rpy="0 0 0"/>
            <geometry>
                <mesh filename="package://robot_urdf/meshes/thigh_link_14.stl" scale="1 1 1"/>
            </geometry>
            <material name="white">
                <color rgba="0.9 0.9 0.9 1"/>
            </material>
        </visual>
        <collision>
            <geometry>
                <mesh filename="package://robot_urdf/meshes/thigh_link_14.stl" scale="1 1 1"/>
            </geometry>
        </collision>
        <inertial>
            <mass value="0.13695392"/>
            <inertia ixx="0.00008188" ixy="0.00000025" ixz="0" iyy="0.00005137" iyz="0.00000016" izz="0.00007680"/>
        </inertial>
    </link>

    <!-- joint 42 -->
    <joint name="joint_42" type="revolute">
        <parent link="thigh_link_41"/>
        <child link="shin_link_42"/>
        <origin xyz="0 0.07109 0" rpy="0 0 0"/>  <!-- Position relative to parent -->
        <axis xyz="1 0 0"/>
        <limit lower="-1.5712" upper="1.5712" effort="4.5" velocity="3.0"/>
    </joint>

    <!-- Shin Link 42 -->
    <link name="shin_link_42">
        <visual>
            <origin xyz="0 0 0" rpy="0 0 0"/>
            <geometry>
                <mesh filename="package://robot_urdf/meshes/shin_link_14.stl" scale="1 1 1"/>
            </geometry>
            <material name="white">
                <color rgba="0.1 0.1 0.1 1"/>
            </material>
        </visual>
        <collision>
            <geometry>
                <mesh filename="package://robot_urdf/meshes/shin_link_14.stl" scale="1 1 1"/>
            </geometry>
        </collision>
        <inertial>
            <mass value="0.15177213"/>
            <inertia ixx="0.00008751" ixy="0.00000046" ixz="0" iyy="0.00006200" iyz="0" izz="0.00012088"/>
        </inertial>
    </link>

    <!-- joint 43 -->
    <joint name="joint_43" type="revolute">
        <parent link="shin_link_42"/>
        <child link="foot_link_43"/>
        <origin xyz="0 0.08109 0" rpy="0 0 0"/>  <!-- Position relative to parent -->
        <axis xyz="1 0 0"/>
        <limit lower="-1.5712" upper="1.5712" effort="4.5" velocity="3.0"/>
    </joint>

    <!-- Foot Link 43 -->
    <link name="foot_link_43">
        <visual>
            <origin xyz="0 0 0" rpy="0 0 0"/>
            <geometry>
                <mesh filename="package://robot_urdf/meshes/foot_link_14.stl" scale="1 1 1"/>
            </geometry>
            <material name="white">
                <color rgba="0.9 0.9 0.9 1"/>
            </material>
        </visual>
        <collision>
            <geometry>
                <mesh filename="package://robot_urdf/meshes/foot_link_14.stl" scale="1 1 1"/>
            </geometry>
        </collision>
        <inertial>
            <mass value="0.08684425"/>
            <inertia ixx="0.00013083" ixy="0.00000021" ixz="-0.00000003" iyy="0.00004844" iyz="-0.00003099" izz="0.00015571"/>
        </inertial>
    </link>
    <!-- chain 4 end -->

    <!-- chain 2 start -->
    <!-- joint 21 -->
    <joint name="joint_21" type="revolute">
        <parent link="base_link"/>
        <child link="thigh_link_21"/>
        <origin xyz="-0.12804108549 0 0.028165" rpy="0 0 0"/>  <!-- Position relative to parent -->
        <axis xyz="0 0 1"/>
        <limit lower="-1.5712" upper="1.5712" effort="4.5" velocity="3.0"/>
    </joint>

    <!-- Thigh Link 21 -->
    <link name="thigh_link_21">
        <visual>
            <origin xyz="0 0 0" rpy="0 0 0"/>
            <geometry>
                <mesh filename="package://robot_urdf/meshes/thigh_link_2.stl" scale="1 1 1"/>
            </geometry>
            <material name="white">
                <color rgba="0.9 0.9 0.9 1"/>
            </material>
        </visual>
        <collision>
            <geometry>
                <mesh filename="package://robot_urdf/meshes/thigh_link_2.stl" scale="1 1 1"/>
            </geometry>
        </collision>
        <inertial>
            <mass value="0.13695392"/>
            <inertia ixx="0.00008188" ixy="0.00000025" ixz="0" iyy="0.00005137" iyz="0.00000016" izz="0.00007680"/>
        </inertial>
    </link>

    <!-- joint 22 -->
    <joint name="joint_22" type="revolute">
        <parent link="thigh_link_21"/>
        <child link="shin_link_22"/>
        <origin xyz="-0.07109 0 0" rpy="0 0 0"/>  <!-- Position relative to parent -->
        <axis xyz="0 1 0"/>
        <limit lower="-1.5712" upper="1.5712" effort="4.5" velocity="3.0"/>
    </joint>

    <!-- Shin Link 22 -->
    <link name="shin_link_22">
        <visual>
            <origin xyz="0 0 0" rpy="0 0 0"/>
            <geometry>
                <mesh filename="package://robot_urdf/meshes/shin_link_2.stl" scale="1 1 1"/>
            </geometry>
            <material name="white">
                <color rgba="0.1 0.1 0.1 1"/>
            </material>
        </visual>
        <collision>
            <geometry>
                <mesh filename="package://robot_urdf/meshes/shin_link_2.stl" scale="1 1 1"/>
            </geometry>
        </collision>
        <inertial>
            <mass value="0.15177213"/>
            <inertia ixx="0.00008751" ixy="0.00000046" ixz="0" iyy="0.00006200" iyz="0" izz="0.00012088"/>
        </inertial>
    </link>

    <!-- joint 23 -->
    <joint name="joint_23" type="revolute">
        <parent link="shin_link_22"/>
        <child link="foot_link_23"/>
        <origin xyz="-0.08109 0 0" rpy="0 0 0"/>  <!-- Position relative to parent -->
        <axis xyz="0 1 0"/>
        <limit lower="-1.5712" upper="1.5712" effort="4.5" velocity="3.0"/>
    </joint>

    <!-- Foot Link 23 -->
    <link name="foot_link_23">
        <visual>
            <origin xyz="0 0 0" rpy="0 0 0"/>
            <geometry>
                <mesh filename="package://robot_urdf/meshes/foot_link_2.stl" scale="1 1 1"/>
            </geometry>
            <material name="white">
                <color rgba="0.9 0.9 0.9 1"/>
            </material>
        </visual>
        <collision>
            <geometry>
                <mesh filename="package://robot_urdf/meshes/foot_link_2.stl" scale="1 1 1"/>
            </geometry>
        </collision>
        <inertial>
            <mass value="0.08684425"/>
            <inertia ixx="0.00013083" ixy="0.00000021" ixz="-0.00000003" iyy="0.00004844" iyz="-0.00003099" izz="0.00015571"/>
        </inertial>
    </link>
    <!-- chain 2 end -->

    <!-- chain 5 start -->
    <!-- joint 51 -->
    <joint name="joint_51" type="revolute">
        <parent link="base_link"/>
        <child link="thigh_link_51"/>
        <origin xyz="0.12804108549 0 0.028165" rpy="0 0 0"/>  <!-- Position relative to parent -->
        <axis xyz="0 0 1"/>
        <limit lower="-1.5712" upper="1.5712" effort="4.5" velocity="3.0"/>
    </joint>

    <!-- Thigh Link 51 -->
    <link name="thigh_link_51">
        <visual>
            <origin xyz="0 0 0" rpy="0 0 0"/>
            <geometry>
                <mesh filename="package://robot_urdf/meshes/thigh_link_5.stl" scale="1 1 1"/>
            </geometry>
            <material name="white">
                <color rgba="0.9 0.9 0.9 1"/>
            </material>
        </visual>
        <collision>
            <geometry>
                <mesh filename="package://robot_urdf/meshes/thigh_link_5.stl" scale="1 1 1"/>
            </geometry>
        </collision>
        <inertial>
            <mass value="0.13695392"/>
            <inertia ixx="0.00008188" ixy="0.00000025" ixz="0" iyy="0.00005137" iyz="0.00000016" izz="0.00007680"/>
        </inertial>
    </link>

    <!-- joint 52 -->
    <joint name="joint_52" type="revolute">
        <parent link="thigh_link_51"/>
        <child link="shin_link_52"/>
        <origin xyz="0.07109 0 0" rpy="0 0 0"/>  <!-- Position relative to parent -->
        <axis xyz="0 -1 0"/>
        <limit lower="-1.5712" upper="1.5712" effort="4.5" velocity="3.0"/>
    </joint>

    <!-- Shin Link 52 -->
    <link name="shin_link_52">
        <visual>
            <origin xyz="0 0 0" rpy="0 0 0"/>
            <geometry>
                <mesh filename="package://robot_urdf/meshes/shin_link_5.stl" scale="1 1 1"/>
            </geometry>
            <material name="white">
                <color rgba="0.1 0.1 0.1 1"/>
            </material>
        </visual>
        <collision>
            <geometry>
                <mesh filename="package://robot_urdf/meshes/shin_link_5.stl" scale="1 1 1"/>
            </geometry>
        </collision>
        <inertial>
            <mass value="0.15177213"/>
            <inertia ixx="0.00008751" ixy="0.00000046" ixz="0" iyy="0.00006200" iyz="0" izz="0.00012088"/>
        </inertial>
    </link>

    <!-- joint 53 -->
    <joint name="joint_53" type="revolute">
        <parent link="shin_link_52"/>
        <child link="foot_link_53"/>
        <origin xyz="0.08109 0 0" rpy="0 0 0"/>  <!-- Position relative to parent -->
        <axis xyz="0 -1 0"/>
        <limit lower="-1.5712" upper="1.5712" effort="4.5" velocity="3.0"/>
    </joint>

    <!-- Foot Link 53 -->
    <link name="foot_link_53">
        <visual>
            <origin xyz="0 0 0" rpy="0 0 0"/>
            <geometry>
                <mesh filename="package://robot_urdf/meshes/foot_link_5.stl" scale="1 1 1"/>
            </geometry>
            <material name="white">
                <color rgba="0.9 0.9 0.9 1"/>
            </material>
        </visual>
        <collision>
            <geometry>
                <mesh filename="package://robot_urdf/meshes/foot_link_5.stl" scale="1 1 1"/>
            </geometry>
        </collision>
        <inertial>
            <mass value="0.08684425"/>
            <inertia ixx="0.00013083" ixy="0.00000021" ixz="-0.00000003" iyy="0.00004844" iyz="-0.00003099" izz="0.00015571"/>
        </inertial>
    </link>
    <!-- chain 5 end -->

    <!-- chain 6 start -->
    <!-- joint 61 -->
    <joint name="joint_61" type="revolute">
        <parent link="base_link"/>
        <child link="thigh_link_61"/>
        <origin xyz="0.06402054275 -0.11088683276 0.028165" rpy="0 0 0"/>  <!-- Position relative to parent -->
        <axis xyz="0 0 1"/>
        <limit lower="-1.0472" upper="2.0944" effort="4.5" velocity="3.0"/>
    </joint>

    <!-- Thigh Link 61 -->
    <link name="thigh_link_61">
        <visual>
            <origin xyz="0 0 0" rpy="0 0 0"/>
            <geometry>
                <mesh filename="package://robot_urdf/meshes/thigh_link_36.stl" scale="1 1 1"/>
            </geometry>
            <material name="white">
                <color rgba="0.9 0.9 0.9 1"/>
            </material>
        </visual>
        <collision>
            <geometry>
                <mesh filename="package://robot_urdf/meshes/thigh_link_36.stl" scale="1 1 1"/>
            </geometry>
        </collision>
        <inertial>
            <mass value="0.13695392"/>
            <inertia ixx="0.00008188" ixy="0.00000025" ixz="0" iyy="0.00005137" iyz="0.00000016" izz="0.00007680"/>
        </inertial>
    </link>

    <!-- joint 62 -->
    <joint name="joint_62" type="revolute">
        <parent link="thigh_link_61"/>
        <child link="shin_link_62"/>
        <origin xyz="0 -0.07109 0" rpy="0 0 0"/>  <!-- Position relative to parent -->
        <axis xyz="-1 0 0"/>
        <limit lower="-1.5712" upper="1.5712" effort="4.5" velocity="3.0"/>
    </joint>

    <!-- Shin Link 62 -->
    <link name="shin_link_62">
        <visual>
            <origin xyz="0 0 0" rpy="0 0 0"/>
            <geometry>
                <mesh filename="package://robot_urdf/meshes/shin_link_36.stl" scale="1 1 1"/>
            </geometry>
            <material name="white">
                <color rgba="0.1 0.1 0.1 1"/>
            </material>
        </visual>
        <collision>
            <geometry>
                <mesh filename="package://robot_urdf/meshes/shin_link_36.stl" scale="1 1 1"/>
            </geometry>
        </collision>
        <inertial>
            <mass value="0.15177213"/>
            <inertia ixx="0.00008751" ixy="0.00000046" ixz="0" iyy="0.00006200" iyz="0" izz="0.00012088"/>
        </inertial>
    </link>

    <!-- joint 63 -->
    <joint name="joint_63" type="revolute">
        <parent link="shin_link_62"/>
        <child link="foot_link_63"/>
        <origin xyz="0 -0.08109 0" rpy="0 0 0"/>  <!-- Position relative to parent -->
        <axis xyz="-1 0 0"/>
        <limit lower="-1.5712" upper="1.5712" effort="4.5" velocity="3.0"/>
    </joint>

    <!-- Foot Link 63 -->
    <link name="foot_link_63">
        <visual>
            <origin xyz="0 0 0" rpy="0 0 0"/>
            <geometry>
                <mesh filename="package://robot_urdf/meshes/foot_link_36.stl" scale="1 1 1"/>
            </geometry>
            <material name="white">
                <color rgba="0.9 0.9 0.9 1"/>
            </material>
        </visual>
        <collision>
            <geometry>
                <mesh filename="package://robot_urdf/meshes/foot_link_36.stl" scale="1 1 1"/>
            </geometry>
        </collision>
        <inertial>
            <mass value="0.08684425"/>
            <inertia ixx="0.00013083" ixy="0.00000021" ixz="-0.00000003" iyy="0.00004844" iyz="-0.00003099" izz="0.00015571"/>
        </inertial>
    </link>
    <!-- chain 6 end -->

    <!-- chain 3 start -->
    <!-- joint 31 -->
    <joint name="joint_31" type="revolute">
        <parent link="base_link"/>
        <child link="thigh_link_31"/>
        <origin xyz="-0.06402054275 -0.11088683276 0.028165" rpy="0 0 0"/>  <!-- Position relative to parent -->
        <axis xyz="0 0 1"/>
        <limit lower="-2.0944" upper="1.0472" effort="4.5" velocity="3.0"/>
    </joint>

    <!-- Thigh Link 31 -->
    <link name="thigh_link_31">
        <visual>
            <origin xyz="0 0 0" rpy="0 0 0"/>
            <geometry>
                <mesh filename="package://robot_urdf/meshes/thigh_link_36.stl" scale="1 1 1"/>
            </geometry>
            <material name="white">
                <color rgba="0.9 0.9 0.9 1"/>
            </material>
        </visual>
        <collision>
            <geometry>
                <mesh filename="package://robot_urdf/meshes/thigh_link_36.stl" scale="1 1 1"/>
            </geometry>
        </collision>
        <inertial>
            <mass value="0.13695392"/>
            <inertia ixx="0.00008188" ixy="0.00000025" ixz="0" iyy="0.00005137" iyz="0.00000016" izz="0.00007680"/>
        </inertial>
    </link>

    <!-- joint 32 -->
    <joint name="joint_32" type="revolute">
        <parent link="thigh_link_31"/>
        <child link="shin_link_32"/>
        <origin xyz="0 -0.07109 0" rpy="0 0 0"/>  <!-- Position relative to parent -->
        <axis xyz="-1 0 0"/>
        <limit lower="-1.5712" upper="1.5712" effort="4.5" velocity="3.0"/>
    </joint>

    <!-- Shin Link 32 -->
    <link name="shin_link_32">
        <visual>
            <origin xyz="0 0 0" rpy="0 0 0"/>
            <geometry>
                <mesh filename="package://robot_urdf/meshes/shin_link_36.stl" scale="1 1 1"/>
            </geometry>
            <material name="white">
                <color rgba="0.1 0.1 0.1 1"/>
            </material>
        </visual>
        <collision>
            <geometry>
                <mesh filename="package://robot_urdf/meshes/shin_link_36.stl" scale="1 1 1"/>
            </geometry>
        </collision>
        <inertial>
            <mass value="0.15177213"/>
            <inertia ixx="0.00008751" ixy="0.00000046" ixz="0" iyy="0.00006200" iyz="0" izz="0.00012088"/>
        </inertial>
    </link>

    <!-- joint 33 -->
    <joint name="joint_33" type="revolute">
        <parent link="shin_link_32"/>
        <child link="foot_link_33"/>
        <origin xyz="0 -0.08109 0" rpy="0 0 0"/>  <!-- Position relative to parent -->
        <axis xyz="-1 0 0"/>
        <limit lower="-1.5712" upper="1.5712" effort="4.5" velocity="3.0"/>
    </joint>

    <!-- Foot Link 33 -->
    <link name="foot_link_33">
        <visual>
            <origin xyz="0 0 0" rpy="0 0 0"/>
            <geometry>
                <mesh filename="package://robot_urdf/meshes/foot_link_36.stl" scale="1 1 1"/>
            </geometry>
            <material name="white">
                <color rgba="0.9 0.9 0.9 1"/>
            </material>
        </visual>
        <collision>
            <geometry>
                <mesh filename="package://robot_urdf/meshes/foot_link_36.stl" scale="1 1 1"/>
            </geometry>
        </collision>
        <inertial>
            <mass value="0.08684425"/>
            <inertia ixx="0.00013083" ixy="0.00000021" ixz="-0.00000003" iyy="0.00004844" iyz="-0.00003099" izz="0.00015571"/>
        </inertial>
    </link>
    <!-- chain 3 end -->
    
</robot>
